[2025-01-05T21:30:25.396+0000] {local_task_job_runner.py:120} INFO - ::group::Pre task execution logs
[2025-01-05T21:30:25.408+0000] {taskinstance.py:2076} INFO - Dependencies all met for dep_context=non-requeueable deps ti=<TaskInstance: raw_banking_tinkoff.file_processing manual__2025-01-05T21:30:17.575237+00:00 [queued]>
[2025-01-05T21:30:25.411+0000] {taskinstance.py:2076} INFO - Dependencies all met for dep_context=requeueable deps ti=<TaskInstance: raw_banking_tinkoff.file_processing manual__2025-01-05T21:30:17.575237+00:00 [queued]>
[2025-01-05T21:30:25.411+0000] {taskinstance.py:2306} INFO - Starting attempt 2 of 2
[2025-01-05T21:30:25.416+0000] {taskinstance.py:2330} INFO - Executing <Task(PythonOperator): file_processing> on 2025-01-05 21:30:17.575237+00:00
[2025-01-05T21:30:25.420+0000] {standard_task_runner.py:90} INFO - Running: ['airflow', 'tasks', 'run', 'raw_banking_tinkoff', 'file_processing', 'manual__2025-01-05T21:30:17.575237+00:00', '--job-id', '77', '--raw', '--subdir', 'DAGS_FOLDER/raw_banking_tinkoff.py', '--cfg-path', '/tmp/tmpa27qs6bs']
[2025-01-05T21:30:25.421+0000] {logging_mixin.py:188} WARNING - /home/airflow/.local/lib/python3.12/site-packages/airflow/task/task_runner/standard_task_runner.py:61 DeprecationWarning: This process (pid=377) is multi-threaded, use of fork() may lead to deadlocks in the child.
[2025-01-05T21:30:25.421+0000] {standard_task_runner.py:91} INFO - Job 77: Subtask file_processing
[2025-01-05T21:30:25.421+0000] {standard_task_runner.py:63} INFO - Started process 379 to run task
[2025-01-05T21:30:25.440+0000] {task_command.py:426} INFO - Running <TaskInstance: raw_banking_tinkoff.file_processing manual__2025-01-05T21:30:17.575237+00:00 [running]> on host 6d9883a799ac
[2025-01-05T21:30:25.471+0000] {taskinstance.py:2648} INFO - Exporting env vars: AIRFLOW_CTX_DAG_OWNER='nmashtakov' AIRFLOW_CTX_DAG_ID='raw_banking_tinkoff' AIRFLOW_CTX_TASK_ID='file_processing' AIRFLOW_CTX_EXECUTION_DATE='2025-01-05T21:30:17.575237+00:00' AIRFLOW_CTX_TRY_NUMBER='2' AIRFLOW_CTX_DAG_RUN_ID='manual__2025-01-05T21:30:17.575237+00:00'
[2025-01-05T21:30:25.472+0000] {taskinstance.py:430} INFO - ::endgroup::
[2025-01-05T21:30:25.565+0000] {taskinstance.py:441} INFO - ::group::Post task execution logs
[2025-01-05T21:30:25.565+0000] {taskinstance.py:2905} ERROR - Task failed with exception
Traceback (most recent call last):
  File "/home/airflow/.local/lib/python3.12/site-packages/airflow/models/taskinstance.py", line 465, in _execute_task
    result = _execute_callable(context=context, **execute_callable_kwargs)
             ^^^^^^^^^^^^^^^^^^^^^^^^^^^^^^^^^^^^^^^^^^^^^^^^^^^^^^^^^^^^^
  File "/home/airflow/.local/lib/python3.12/site-packages/airflow/models/taskinstance.py", line 432, in _execute_callable
    return execute_callable(context=context, **execute_callable_kwargs)
           ^^^^^^^^^^^^^^^^^^^^^^^^^^^^^^^^^^^^^^^^^^^^^^^^^^^^^^^^^^^^
  File "/home/airflow/.local/lib/python3.12/site-packages/airflow/models/baseoperator.py", line 401, in wrapper
    return func(self, *args, **kwargs)
           ^^^^^^^^^^^^^^^^^^^^^^^^^^^
  File "/home/airflow/.local/lib/python3.12/site-packages/airflow/operators/python.py", line 235, in execute
    return_value = self.execute_callable()
                   ^^^^^^^^^^^^^^^^^^^^^^^
  File "/home/airflow/.local/lib/python3.12/site-packages/airflow/operators/python.py", line 252, in execute_callable
    return self.python_callable(*self.op_args, **self.op_kwargs)
           ^^^^^^^^^^^^^^^^^^^^^^^^^^^^^^^^^^^^^^^^^^^^^^^^^^^^^
  File "/opt/airflow/dags/raw_banking_tinkoff.py", line 47, in file_processing
    kwargs['ti'].xcom_push(key='to_db', value=to_db.sort_values('Дата операции').to_dict())
                                              ^^^^^^^^^^^^^^^^^^^^^^^^^^^^^^^^^^
  File "/home/airflow/.local/lib/python3.12/site-packages/pandas/core/frame.py", line 6944, in sort_values
    k = self._get_label_or_level_values(by[0], axis=axis)
        ^^^^^^^^^^^^^^^^^^^^^^^^^^^^^^^^^^^^^^^^^^^^^^^^^
  File "/home/airflow/.local/lib/python3.12/site-packages/pandas/core/generic.py", line 1844, in _get_label_or_level_values
    raise KeyError(key)
KeyError: 'Дата операции'
[2025-01-05T21:30:25.572+0000] {taskinstance.py:1206} INFO - Marking task as FAILED. dag_id=raw_banking_tinkoff, task_id=file_processing, run_id=manual__2025-01-05T21:30:17.575237+00:00, execution_date=20250105T213017, start_date=20250105T213025, end_date=20250105T213025
[2025-01-05T21:30:25.577+0000] {standard_task_runner.py:110} ERROR - Failed to execute job 77 for task file_processing ('Дата операции'; 379)
[2025-01-05T21:30:25.609+0000] {local_task_job_runner.py:240} INFO - Task exited with return code 1
[2025-01-05T21:30:25.622+0000] {taskinstance.py:3503} INFO - 0 downstream tasks scheduled from follow-on schedule check
[2025-01-05T21:30:25.624+0000] {local_task_job_runner.py:222} INFO - ::endgroup::
