[2025-01-05T21:29:38.985+0000] {local_task_job_runner.py:120} INFO - ::group::Pre task execution logs
[2025-01-05T21:29:38.998+0000] {taskinstance.py:2076} INFO - Dependencies all met for dep_context=non-requeueable deps ti=<TaskInstance: raw_banking_tinkoff.file_processing manual__2025-01-05T21:29:30.595607+00:00 [queued]>
[2025-01-05T21:29:39.001+0000] {taskinstance.py:2076} INFO - Dependencies all met for dep_context=requeueable deps ti=<TaskInstance: raw_banking_tinkoff.file_processing manual__2025-01-05T21:29:30.595607+00:00 [queued]>
[2025-01-05T21:29:39.001+0000] {taskinstance.py:2306} INFO - Starting attempt 2 of 2
[2025-01-05T21:29:39.006+0000] {taskinstance.py:2330} INFO - Executing <Task(PythonOperator): file_processing> on 2025-01-05 21:29:30.595607+00:00
[2025-01-05T21:29:39.010+0000] {standard_task_runner.py:90} INFO - Running: ['airflow', 'tasks', 'run', 'raw_banking_tinkoff', 'file_processing', 'manual__2025-01-05T21:29:30.595607+00:00', '--job-id', '74', '--raw', '--subdir', 'DAGS_FOLDER/raw_banking_tinkoff.py', '--cfg-path', '/tmp/tmpcpt1inmv']
[2025-01-05T21:29:39.011+0000] {standard_task_runner.py:91} INFO - Job 74: Subtask file_processing
[2025-01-05T21:29:39.011+0000] {logging_mixin.py:188} WARNING - /home/airflow/.local/lib/python3.12/site-packages/airflow/task/task_runner/standard_task_runner.py:61 DeprecationWarning: This process (pid=346) is multi-threaded, use of fork() may lead to deadlocks in the child.
[2025-01-05T21:29:39.013+0000] {standard_task_runner.py:63} INFO - Started process 348 to run task
[2025-01-05T21:29:39.033+0000] {task_command.py:426} INFO - Running <TaskInstance: raw_banking_tinkoff.file_processing manual__2025-01-05T21:29:30.595607+00:00 [running]> on host 6d9883a799ac
[2025-01-05T21:29:39.067+0000] {taskinstance.py:2648} INFO - Exporting env vars: AIRFLOW_CTX_DAG_OWNER='nmashtakov' AIRFLOW_CTX_DAG_ID='raw_banking_tinkoff' AIRFLOW_CTX_TASK_ID='file_processing' AIRFLOW_CTX_EXECUTION_DATE='2025-01-05T21:29:30.595607+00:00' AIRFLOW_CTX_TRY_NUMBER='2' AIRFLOW_CTX_DAG_RUN_ID='manual__2025-01-05T21:29:30.595607+00:00'
[2025-01-05T21:29:39.068+0000] {taskinstance.py:430} INFO - ::endgroup::
[2025-01-05T21:29:39.171+0000] {taskinstance.py:441} INFO - ::group::Post task execution logs
[2025-01-05T21:29:39.171+0000] {taskinstance.py:2905} ERROR - Task failed with exception
Traceback (most recent call last):
  File "/home/airflow/.local/lib/python3.12/site-packages/airflow/models/taskinstance.py", line 465, in _execute_task
    result = _execute_callable(context=context, **execute_callable_kwargs)
             ^^^^^^^^^^^^^^^^^^^^^^^^^^^^^^^^^^^^^^^^^^^^^^^^^^^^^^^^^^^^^
  File "/home/airflow/.local/lib/python3.12/site-packages/airflow/models/taskinstance.py", line 432, in _execute_callable
    return execute_callable(context=context, **execute_callable_kwargs)
           ^^^^^^^^^^^^^^^^^^^^^^^^^^^^^^^^^^^^^^^^^^^^^^^^^^^^^^^^^^^^
  File "/home/airflow/.local/lib/python3.12/site-packages/airflow/models/baseoperator.py", line 401, in wrapper
    return func(self, *args, **kwargs)
           ^^^^^^^^^^^^^^^^^^^^^^^^^^^
  File "/home/airflow/.local/lib/python3.12/site-packages/airflow/operators/python.py", line 235, in execute
    return_value = self.execute_callable()
                   ^^^^^^^^^^^^^^^^^^^^^^^
  File "/home/airflow/.local/lib/python3.12/site-packages/airflow/operators/python.py", line 252, in execute_callable
    return self.python_callable(*self.op_args, **self.op_kwargs)
           ^^^^^^^^^^^^^^^^^^^^^^^^^^^^^^^^^^^^^^^^^^^^^^^^^^^^^
  File "/opt/airflow/dags/raw_banking_tinkoff.py", line 43, in file_processing
    to_db.columns = ['operation_date', 'payment_date', 'card_number', 'status', 'amount',
    ^^^^^^^^^^^^^
  File "/home/airflow/.local/lib/python3.12/site-packages/pandas/core/generic.py", line 6218, in __setattr__
    return object.__setattr__(self, name, value)
           ^^^^^^^^^^^^^^^^^^^^^^^^^^^^^^^^^^^^^
  File "properties.pyx", line 69, in pandas._libs.properties.AxisProperty.__set__
  File "/home/airflow/.local/lib/python3.12/site-packages/pandas/core/generic.py", line 767, in _set_axis
    self._mgr.set_axis(axis, labels)
  File "/home/airflow/.local/lib/python3.12/site-packages/pandas/core/internals/managers.py", line 227, in set_axis
    self._validate_set_axis(axis, new_labels)
  File "/home/airflow/.local/lib/python3.12/site-packages/pandas/core/internals/base.py", line 85, in _validate_set_axis
    raise ValueError(
ValueError: Length mismatch: Expected axis has 15 elements, new values have 17 elements
[2025-01-05T21:29:39.177+0000] {taskinstance.py:1206} INFO - Marking task as FAILED. dag_id=raw_banking_tinkoff, task_id=file_processing, run_id=manual__2025-01-05T21:29:30.595607+00:00, execution_date=20250105T212930, start_date=20250105T212938, end_date=20250105T212939
[2025-01-05T21:29:39.181+0000] {standard_task_runner.py:110} ERROR - Failed to execute job 74 for task file_processing (Length mismatch: Expected axis has 15 elements, new values have 17 elements; 348)
[2025-01-05T21:29:39.201+0000] {local_task_job_runner.py:240} INFO - Task exited with return code 1
[2025-01-05T21:29:39.211+0000] {taskinstance.py:3503} INFO - 0 downstream tasks scheduled from follow-on schedule check
[2025-01-05T21:29:39.213+0000] {local_task_job_runner.py:222} INFO - ::endgroup::
