[2025-01-05T21:29:32.791+0000] {local_task_job_runner.py:120} INFO - ::group::Pre task execution logs
[2025-01-05T21:29:32.804+0000] {taskinstance.py:2076} INFO - Dependencies all met for dep_context=non-requeueable deps ti=<TaskInstance: raw_banking_tinkoff.file_processing manual__2025-01-05T21:29:30.595607+00:00 [queued]>
[2025-01-05T21:29:32.807+0000] {taskinstance.py:2076} INFO - Dependencies all met for dep_context=requeueable deps ti=<TaskInstance: raw_banking_tinkoff.file_processing manual__2025-01-05T21:29:30.595607+00:00 [queued]>
[2025-01-05T21:29:32.807+0000] {taskinstance.py:2306} INFO - Starting attempt 1 of 2
[2025-01-05T21:29:32.812+0000] {taskinstance.py:2330} INFO - Executing <Task(PythonOperator): file_processing> on 2025-01-05 21:29:30.595607+00:00
[2025-01-05T21:29:32.815+0000] {standard_task_runner.py:90} INFO - Running: ['airflow', 'tasks', 'run', 'raw_banking_tinkoff', 'file_processing', 'manual__2025-01-05T21:29:30.595607+00:00', '--job-id', '73', '--raw', '--subdir', 'DAGS_FOLDER/raw_banking_tinkoff.py', '--cfg-path', '/tmp/tmp0mqlur4l']
[2025-01-05T21:29:32.817+0000] {standard_task_runner.py:91} INFO - Job 73: Subtask file_processing
[2025-01-05T21:29:32.816+0000] {logging_mixin.py:188} WARNING - /home/airflow/.local/lib/python3.12/site-packages/airflow/task/task_runner/standard_task_runner.py:61 DeprecationWarning: This process (pid=343) is multi-threaded, use of fork() may lead to deadlocks in the child.
[2025-01-05T21:29:32.818+0000] {standard_task_runner.py:63} INFO - Started process 345 to run task
[2025-01-05T21:29:32.836+0000] {task_command.py:426} INFO - Running <TaskInstance: raw_banking_tinkoff.file_processing manual__2025-01-05T21:29:30.595607+00:00 [running]> on host 6d9883a799ac
[2025-01-05T21:29:32.868+0000] {taskinstance.py:2648} INFO - Exporting env vars: AIRFLOW_CTX_DAG_OWNER='nmashtakov' AIRFLOW_CTX_DAG_ID='raw_banking_tinkoff' AIRFLOW_CTX_TASK_ID='file_processing' AIRFLOW_CTX_EXECUTION_DATE='2025-01-05T21:29:30.595607+00:00' AIRFLOW_CTX_TRY_NUMBER='1' AIRFLOW_CTX_DAG_RUN_ID='manual__2025-01-05T21:29:30.595607+00:00'
[2025-01-05T21:29:32.869+0000] {taskinstance.py:430} INFO - ::endgroup::
[2025-01-05T21:29:32.971+0000] {taskinstance.py:441} INFO - ::group::Post task execution logs
[2025-01-05T21:29:32.971+0000] {taskinstance.py:2905} ERROR - Task failed with exception
Traceback (most recent call last):
  File "/home/airflow/.local/lib/python3.12/site-packages/airflow/models/taskinstance.py", line 465, in _execute_task
    result = _execute_callable(context=context, **execute_callable_kwargs)
             ^^^^^^^^^^^^^^^^^^^^^^^^^^^^^^^^^^^^^^^^^^^^^^^^^^^^^^^^^^^^^
  File "/home/airflow/.local/lib/python3.12/site-packages/airflow/models/taskinstance.py", line 432, in _execute_callable
    return execute_callable(context=context, **execute_callable_kwargs)
           ^^^^^^^^^^^^^^^^^^^^^^^^^^^^^^^^^^^^^^^^^^^^^^^^^^^^^^^^^^^^
  File "/home/airflow/.local/lib/python3.12/site-packages/airflow/models/baseoperator.py", line 401, in wrapper
    return func(self, *args, **kwargs)
           ^^^^^^^^^^^^^^^^^^^^^^^^^^^
  File "/home/airflow/.local/lib/python3.12/site-packages/airflow/operators/python.py", line 235, in execute
    return_value = self.execute_callable()
                   ^^^^^^^^^^^^^^^^^^^^^^^
  File "/home/airflow/.local/lib/python3.12/site-packages/airflow/operators/python.py", line 252, in execute_callable
    return self.python_callable(*self.op_args, **self.op_kwargs)
           ^^^^^^^^^^^^^^^^^^^^^^^^^^^^^^^^^^^^^^^^^^^^^^^^^^^^^
  File "/opt/airflow/dags/raw_banking_tinkoff.py", line 43, in file_processing
    to_db.columns = ['operation_date', 'payment_date', 'card_number', 'status', 'amount',
    ^^^^^^^^^^^^^
  File "/home/airflow/.local/lib/python3.12/site-packages/pandas/core/generic.py", line 6218, in __setattr__
    return object.__setattr__(self, name, value)
           ^^^^^^^^^^^^^^^^^^^^^^^^^^^^^^^^^^^^^
  File "properties.pyx", line 69, in pandas._libs.properties.AxisProperty.__set__
  File "/home/airflow/.local/lib/python3.12/site-packages/pandas/core/generic.py", line 767, in _set_axis
    self._mgr.set_axis(axis, labels)
  File "/home/airflow/.local/lib/python3.12/site-packages/pandas/core/internals/managers.py", line 227, in set_axis
    self._validate_set_axis(axis, new_labels)
  File "/home/airflow/.local/lib/python3.12/site-packages/pandas/core/internals/base.py", line 85, in _validate_set_axis
    raise ValueError(
ValueError: Length mismatch: Expected axis has 15 elements, new values have 17 elements
[2025-01-05T21:29:32.977+0000] {taskinstance.py:1206} INFO - Marking task as UP_FOR_RETRY. dag_id=raw_banking_tinkoff, task_id=file_processing, run_id=manual__2025-01-05T21:29:30.595607+00:00, execution_date=20250105T212930, start_date=20250105T212932, end_date=20250105T212932
[2025-01-05T21:29:32.981+0000] {standard_task_runner.py:110} ERROR - Failed to execute job 73 for task file_processing (Length mismatch: Expected axis has 15 elements, new values have 17 elements; 345)
[2025-01-05T21:29:33.006+0000] {local_task_job_runner.py:240} INFO - Task exited with return code 1
[2025-01-05T21:29:33.016+0000] {taskinstance.py:3503} INFO - 0 downstream tasks scheduled from follow-on schedule check
[2025-01-05T21:29:33.016+0000] {local_task_job_runner.py:222} INFO - ::endgroup::
